Workbook
Name mu_GMV: #REF!
Name mu_MRR: #REF!
Name sigma2_GMV: #REF!
Name sigma2_MRR: #REF!

Sheet Dashboard

Sheet Constituents
A1: Prices | G1: Daily Returns
B2: a Very very long String is good | C2: a Very very long String is good | D2: a Very very long String is good | H2: a Very very long String is good | I2: a Very very long String is good | J2: a Very very long String is good
A3: Category | B3: Large & Mid Cap | C3: Conservative Hybrid | D3: ESG | E3: Benchmark | G3: Category | H3: Large & Mid Cap | I3: Conservative Hybrid | J3: ESG | K3: Benchmark
A4: Fund | B4: Bandhan Large & Mid Cap Fund - Direct Plan - Growth | C4: Kotak Debt Hybrid Fund - Direct Plan | D4: quant ESG Integration Strategy Fund - Growth Option - Direct Plan | E4: NIFTY 500 | G4: Fund | H4: Bandhan Large & Mid Cap Fund - Direct Plan - Growth | I4: Kotak Debt Hybrid Fund - Direct Plan | J4: quant ESG Integration Strategy Fund - Growth Option - Direct Plan | K4: NIFTY 500
A5: 44141 | B5: 50.77 | C5: 99.5382 | D5: 10.0365 | E5: 10033.5 | G5: 44141
A6: 44144 | B6: 51.32 | C6: 99.8561 | D6: 10.0647 | E6: 10176.35 | G6: 44144 | H6: =B6/B5 -1 -> 0.010833169 | I6: =C6/C5 -1 -> 0.0031937487 | J6: =D6/D5 -1 -> 0.0028097444 | K6: =E6/E5 -1 -> 0.014237305
A7: 44145 | B7: 51.28 | C7: 99.9785 | D7: 10.0624 | E7: 10269 | G7: 44145 | H7: =B7/B6 -1 -> -0.00077942323 | I7: =C7/C6 -1 -> 0.0012257639 | J7: =D7/D6 -1 -> -0.00022852147 | K7: =E7/E6 -1 -> 0.0091044431
A8: 44146 | B8: 51.73 | C8: 100.1093 | D8: 10.1112 | E8: 10356.5 | G8: 44146 | H8: =B8/B7 -1 -> 0.008775351 | I8: =C8/C7 -1 -> 0.0013082813 | J8: =D8/D7 -1 -> 0.0048497376 | K8: =E8/E7 -1 -> 0.0085207907
A9: 44147 | B9: 51.78 | C9: 100.1619 | D9: 10.1635 | E9: 10342.7 | G9: 44147 | H9: =B9/B8 -1 -> 0.00096655712 | I9: =C9/C8 -1 -> 0.00052542571 | J9: =D9/D8 -1 -> 0.005172482 | K9: =E9/E8 -1 -> -0.0013324965
A10: 44148 | B10: 51.99 | C10: 100.1894 | D10: 10.1987 | E10: 10387.2 | G10: 44148 | H10: =B10/B9 -1 -> 0.0040556199 | I10: =C10/C9 -1 -> 0.00027455549 | J10: =D10/D9 -1 -> 0.0034633738 | K10: =E10/E9 -1 -> 0.0043025516
A11: 44152 | B11: 52.94 | C11: 100.6509 | D11: 10.3067 | E11: 10524 | G11: 44152 | H11: =B11/B10 -1 -> 0.018272745 | I11: =C11/C10 -1 -> 0.0046062757 | J11: =D11/D10 -1 -> 0.010589585 | K11: =E11/E10 -1 -> 0.013170055
A12: 44153 | B12: 53.22 | C12: 100.8591 | D12: 10.3592 | E12: 10588.35 | G12: 44153 | H12: =B12/B11 -1 -> 0.0052890064 | I12: =C12/C11 -1 -> 0.0020685359 | J12: =D12/D11 -1 -> 0.005093774 | K12: =E12/E11 -1 -> 0.0061145952
A13: 44154 | B13: 52.72 | C13: 100.6276 | D13: 10.285 | E13: 10477.5 | G13: 44154 | H13: =B13/B12 -1 -> -0.0093949643 | I13: =C13/C12 -1 -> -0.0022952812 | J13: =D13/D12 -1 -> -0.0071627153 | K13: =E13/E12 -1 -> -0.010469053
A14: 44155 | B14: 53.12 | C14: 101.2298 | D14: 10.3038 | E14: 10560.55 | G14: 44155 | H14: =B14/B13 -1 -> 0.0075872534 | I14: =C14/C13 -1 -> 0.0059844416 | J14: =D14/D13 -1 -> 0.0018279047 | K14: =E14/E13 -1 -> 0.0079265092
A15: 44158 | B15: 53.54 | C15: 101.4821 | D15: 10.3289 | E15: 10635.95 | G15: 44158 | H15: =B15/B14 -1 -> 0.0079066265 | I15: =C15/C14 -1 -> 0.0024923491 | J15: =D15/D14 -1 -> 0.0024359945 | K15: =E15/E14 -1 -> 0.0071397797
A16: 44159 | B16: 54.02 | C16: 101.8941 | D16: 10.4732 | E16: 10733.6 | G16: 44159 | H16: =B16/B15 -1 -> 0.0089652596 | I16: =C16/C15 -1 -> 0.0040598293 | J16: =D16/D15 -1 -> 0.01397051 | K16: =E16/E15 -1 -> 0.0091811263
A17: 44160 | B17: 53.16 | C17: 101.8261 | D17: 10.3348 | E17: 10574.95 | G17: 44160 | H17: =B17/B16 -1 -> -0.01592003 | I17: =C17/C16 -1 -> -0.00066735954 | J17: =D17/D16 -1 -> -0.013214681 | K17: =E17/E16 -1 -> -0.014780689
... A1211: 45950 | B1211: 161.837 | C1211: 155.4878 | D1211: 33.1147 | E1211: 23716.1 | G1211: 45950 | H1211: =B1211/B1210 -1 -> 0.0062487565 | I1211: =C1211/C1210 -1 -> 0.0020228917 | J1211: =D1211/D1210 -1 -> 0.0068318638 | K1211: =E1211/E1210 -1 -> 0.005002532

Sheet Moments
A1: Formula covariance matrix | G1: Average returns
B2: 1 | C2: 2 | D2: 3 | H2: Daily | I2: Annual
A3: 1 | B3: =_xlfn.COVARIANCE.P(OFFSET(Constituents!$H$6:$J$1211,0,MAX(Moments!$A3,Moments!B$2)-1),OFFSET(Constituents!$H$6:$J$1211,0,MIN(Moments!$A3,Moments!B$2)-1)) -> 7.186134e-05 | C3: =_xlfn.COVARIANCE.P(OFFSET(Constituents!$H$6:$J$1211,0,MAX(Moments!$A3,Moments!C$2)-1),OFFSET(Constituents!$H$6:$J$1211,0,MIN(Moments!$A3,Moments!C$2)-1)) -> 4.3900008e-05 | D3: =_xlfn.COVARIANCE.P(OFFSET(Constituents!$H$6:$J$1211,0,MAX(Moments!$A3,Moments!D$2)-1),OFFSET(Constituents!$H$6:$J$1211,0,MIN(Moments!$A3,Moments!D$2)-1)) -> 5.5569137e-05 | G3: Bandhan Large & Mid Cap Fund - Direct Plan - Growth | H3: =AVERAGE(Constituents!$H$6:$H$1211) -> 0.0010063122 | I3: =(1+H3)^252 - 1 -> 0.28847992 | K3: since this is normal returns,
A4: 2 | B4: =_xlfn.COVARIANCE.P(OFFSET(Constituents!$H$6:$J$1211,0,MAX(Moments!$A4,Moments!B$2)-1),OFFSET(Constituents!$H$6:$J$1211,0,MIN(Moments!$A4,Moments!B$2)-1)) -> 4.3900008e-05 | C4: =_xlfn.COVARIANCE.P(OFFSET(Constituents!$H$6:$J$1211,0,MAX(Moments!$A4,Moments!C$2)-1),OFFSET(Constituents!$H$6:$J$1211,0,MIN(Moments!$A4,Moments!C$2)-1)) -> 7.0641006e-05 | D4: =_xlfn.COVARIANCE.P(OFFSET(Constituents!$H$6:$J$1211,0,MAX(Moments!$A4,Moments!D$2)-1),OFFSET(Constituents!$H$6:$J$1211,0,MIN(Moments!$A4,Moments!D$2)-1)) -> 5.4913304e-05 | G4: Kotak Debt Hybrid Fund - Direct Plan | H4: =AVERAGE(Constituents!$I$6:$I$1211) -> 0.00037352027 | I4: =(1+H4)^252 - 1 -> 0.098680081 | K4: ="and Arth Mean, we use "&_xlfn.FORMULATEXT(I3) -> and Arth Mean, we use =(1+H3)^252 - 1
A5: 3 | B5: =_xlfn.COVARIANCE.P(OFFSET(Constituents!$H$6:$J$1211,0,MAX(Moments!$A5,Moments!B$2)-1),OFFSET(Constituents!$H$6:$J$1211,0,MIN(Moments!$A5,Moments!B$2)-1)) -> 5.5569137e-05 | C5: =_xlfn.COVARIANCE.P(OFFSET(Constituents!$H$6:$J$1211,0,MAX(Moments!$A5,Moments!C$2)-1),OFFSET(Constituents!$H$6:$J$1211,0,MIN(Moments!$A5,Moments!C$2)-1)) -> 5.4913304e-05 | D5: =_xlfn.COVARIANCE.P(OFFSET(Constituents!$H$6:$J$1211,0,MAX(Moments!$A5,Moments!D$2)-1),OFFSET(Constituents!$H$6:$J$1211,0,MIN(Moments!$A5,Moments!D$2)-1)) -> 0.00010226117 | G5: quant ESG Integration Strategy Fund - Growth Option - Direct Plan | H5: =AVERAGE(Constituents!$J$6:$J$1211) -> 0.0010503021 | I5: =(1+H5)^252 - 1 -> 0.30282792 | K5: 252 is no. of trading days
B6: =_xlfn.FORMULATEXT(B3) -> =COVARIANCE.P(OFFSET(Constituents!$H$6:$J$1211,0,MAX(Moments!$A3,Moments!B$2)-1),OFFSET(Constituents!$H$6:$J$1211,0,MIN(Moments!$A3,Moments!B$2)-1)) | F6: .
A8: Covariance matrix with Data Analysis Tool | G8: Variance of Returns (does not match with VCV matrix outputs)
H9: Daily | I9: Annual
G10: Bandhan Large & Mid Cap Fund - Direct Plan - Growth | H10: =_xlfn.VAR.P(Constituents!$H$6:$H$1211) -> 8.8722338e-05
G11: Kotak Debt Hybrid Fund - Direct Plan | H11: =_xlfn.VAR.P(Constituents!$I$6:$I$1211) -> 7.2135672e-06
G12: quant ESG Integration Strategy Fund - Growth Option - Direct Plan | H12: =_xlfn.VAR.P(Constituents!$J$6:$J$1211) -> 0.00011936132
A15: Full covariance matrix
B16: A very very long string is good | C16: A very very long string is good | D16: A very very long string is good
B17: Bandhan Large & Mid Cap Fund - Direct Plan - Growth | C17: Kotak Debt Hybrid Fund - Direct Plan | D17: quant ESG Integration Strategy Fund - Growth Option - Direct Plan
A18: Bandhan Large & Mid Cap Fund - Direct Plan - Growth
A19: Kotak Debt Hybrid Fund - Direct Plan
A20: quant ESG Integration Strategy Fund - Growth Option - Direct Plan

Sheet GMV
A1: Covariance matrix (∑) | F1: Inverse covariance matrix (∑^(-1))
B2: Bandhan Large & Mid Cap Fund - Direct Plan - Growth | C2: Kotak Debt Hybrid Fund - Direct Plan | D2: quant ESG Integration Strategy Fund - Growth Option - Direct Plan
A3: Bandhan Large & Mid Cap Fund - Direct Plan - Growth | B3: {=Moments!B3:D5} -> 7.186134e-05 | C3: 4.3900008e-05 | D3: 5.5569137e-05 | F3: {=MINVERSE(B3:D5)} -> 27128.724 | G3: -9268.4947 | H3: -9764.7629
A4: Kotak Debt Hybrid Fund - Direct Plan | B4: 4.3900008e-05 | C4: 7.0641006e-05 | D4: 5.4913304e-05 | F4: -9268.4947 | G4: 27466.094 | H4: -9712.5006
A5: quant ESG Integration Strategy Fund - Growth Option - Direct Plan | B5: 5.5569137e-05 | C5: 5.4913304e-05 | D5: 0.00010226117 | F5: -9764.7629 | G5: -9712.5006 | H5: 20300.617
A7: Vector of ones (1) | F7: Matrix product ∑^(-1) * 1
A8: 1 | F8: {=MMULT(_xlfn.ANCHORARRAY(F3),A8:A10)} -> 8095.4662
A9: 1 | F9: 8485.0984
A10: 1 | F10: 823.354
F12: Inner product 1' * ∑^(-1) * 1
F13: =SUMPRODUCT(A8:A10,_xlfn.ANCHORARRAY(F8)) -> 17403.919 | G13: =_xlfn.FORMULATEXT(F13) -> =SUMPRODUCT(A8:A10,F8#)
F14: =SUM(_xlfn.ANCHORARRAY(F8)) -> 17403.919 | G14: =_xlfn.FORMULATEXT(F14) -> =SUM(F8#)
F16: GMV portfolio (∑^(-1) * 1 / (1' * ∑^(-1) * 1))
F17: Bandhan Large & Mid Cap Fund - Direct Plan - Growth | G17: {=_xlfn.ANCHORARRAY(F8)/F13} -> 0.46515192
F18: Kotak Debt Hybrid Fund - Direct Plan | G18: 0.48753954
F19: quant ESG Integration Strategy Fund - Growth Option - Direct Plan | G19: 0.047308541
F21: Sum of weights | G21: =SUM(_xlfn.ANCHORARRAY(G17)) -> 1
F23: Leverage | G23: =SUMIF(_xlfn.ANCHORARRAY(G17),"<"&0) -> 0

Sheet MRR
A1: Covariance matrix (∑) | F1: Inverse covariance matrix (∑^(-1))
B2: Bandhan Large & Mid Cap Fund - Direct Plan - Growth | C2: Kotak Debt Hybrid Fund - Direct Plan | D2: quant ESG Integration Strategy Fund - Growth Option - Direct Plan
A3: Bandhan Large & Mid Cap Fund - Direct Plan - Growth | B3: {=Moments!B3:D5} -> 7.186134e-05 | C3: 4.3900008e-05 | D3: 5.5569137e-05 | F3: {=MINVERSE(B3:D5)} -> 27128.724 | G3: -9268.4947 | H3: -9764.7629
A4: Kotak Debt Hybrid Fund - Direct Plan | B4: 4.3900008e-05 | C4: 7.0641006e-05 | D4: 5.4913304e-05 | F4: -9268.4947 | G4: 27466.094 | H4: -9712.5006
A5: quant ESG Integration Strategy Fund - Growth Option - Direct Plan | B5: 5.5569137e-05 | C5: 5.4913304e-05 | D5: 0.00010226117 | F5: -9764.7629 | G5: -9712.5006 | H5: 20300.617
A7: Vector of ones (1) | F7: Matrix product ∑^(-1) * µ
A8: 1 | F8: {=MMULT(_xlfn.ANCHORARRAY(F3),_xlfn.ANCHORARRAY(A13))} -> 13.582045
A9: 1 | F9: -9.268916
A10: 1 | F10: 7.8675645
A12: Vector of Exp. Ret | F12: Inner product 1' * ∑^(-1) * µ
A13: {=Moments!H3:H5} -> 0.0010063122 | F13: =SUMPRODUCT(A8:A10,_xlfn.ANCHORARRAY(F8)) -> 12.180693 | G13: =_xlfn.FORMULATEXT(F13) -> =SUMPRODUCT(A8:A10,F8#)
A14: 0.00037352027 | F14: =SUM(_xlfn.ANCHORARRAY(F8)) -> 12.180693 | G14: =_xlfn.FORMULATEXT(F14) -> =SUM(F8#)
A15: 0.0010503021
F16: MRR portfolio (∑^(-1) * µ / (1' * ∑^(-1) * µ))
F17: Bandhan Large & Mid Cap Fund - Direct Plan - Growth | G17: {=_xlfn.ANCHORARRAY(F8)/F13} -> 1.1150469
F18: Kotak Debt Hybrid Fund - Direct Plan | G18: -0.76095145
F19: quant ESG Integration Strategy Fund - Growth Option - Direct Plan | G19: 0.64590451
F21: Sum of weights | G21: =SUM(_xlfn.ANCHORARRAY(G17)) -> 1
F23: Leverage | G23: =SUMIF(_xlfn.ANCHORARRAY(G17),"<"&0) -> -0.76095145

Sheet 2FST Optimality
A1: Inputs
A2: Coefficients
A3: A | B3: =GMV!F13 -> 17403.919
A4: B | B4: =MRR!F13 -> 12.180693
A5: C | B5: =SUMPRODUCT(_xlfn.ANCHORARRAY(MRR!A13),MMULT(_xlfn.ANCHORARRAY(MRR!F3),_xlfn.ANCHORARRAY(MRR!A13))) -> 0.018468968
A7: Target Volatility | B7: =SQRT(Moments!C4) -> 0.0084048204 | C7: =_xlfn.FORMULATEXT(B7) -> =SQRT(Moments!C4)
C8: Set as volatility of the Conserv Hyb fund
A9: Expected Returns (Ann.)
A10: Bandhan Large & Mid Cap Fund - Direct Plan - Growth | B10: {=Moments!I3:I5} -> 0.28847992
A11: Kotak Debt Hybrid Fund - Direct Plan | B11: 0.098680081
A12: quant ESG Integration Strategy Fund - Growth Option - Direct Plan | B12: 0.30282792
A14: Risk tolerance parameter
B15: =SQRT((B3*B7^2 - 1)/(B3*B5 - B4^2)) -> 0.036410204 | C15: =_xlfn.FORMULATEXT(B15) -> =SQRT((B3*B7^2 - 1)/(B3*B5 - B4^2))
A17: Outputs
A18: Efficient Portfolio | D18: Solver | E18: Non-zero constraint
A19: Bandhan Large & Mid Cap Fund - Direct Plan - Growth | B19: {=B4*B15*_xlfn.ANCHORARRAY(MRR!G17)+(1-B4*B15)*_xlfn.ANCHORARRAY(GMV!G17)} -> 0.75338135 | E19: 0.28099024
A20: Kotak Debt Hybrid Fund - Direct Plan | B20: -0.066168106 | E20: 0.15
A21: quant ESG Integration Strategy Fund - Growth Option - Direct Plan | B21: 0.31278676 | E21: 0.56900876
B22: =SUM(_xlfn.ANCHORARRAY(B19)) -> 1 | E22: =SUM(E19:E21) -> 0.999999
A24: Portfolio expected return | B24: {=SUMPRODUCT(_xlfn.ANCHORARRAY(B19)*_xlfn.ANCHORARRAY(B10))} -> 0.30552648 | E24: {=SUMPRODUCT(E19:E21*_xlfn.ANCHORARRAY(B10))} -> 0.26817379
A26: Portfolio variance | B26: =SUMPRODUCT(_xlfn.ANCHORARRAY(B19),MMULT(Moments!B3:D5,_xlfn.ANCHORARRAY('2FST Optimality'!B19))) -> 7.0641006e-05 | E26: =SUMPRODUCT(E19:E21,MMULT(Moments!B3:D5,E19:E21)) -> 7.1216402e-05
A27: Portfolio volatility | B27: =SQRT(SUMPRODUCT(_xlfn.ANCHORARRAY(B19),MMULT(Moments!B3:D5,_xlfn.ANCHORARRAY('2FST Optimality'!B19)))) -> 0.0084048204 | E27: =SQRT(SUMPRODUCT(E19:E21,MMULT(Moments!B3:D5,E19:E21))) -> 0.0084389811

Sheet Solver Fixed Mix
A1: Target weights | G1: Euro Positions | J1: Portfolio value | L1: Euro Positions | Q1: Weights | T1: Portfolio Weight | AE1: Portfolio Return
A2: L&MC | B2: Cons Hyb | C2: ESG | F2: Date | G2: =A2 -> L&MC | H2: =B2 -> Cons Hyb | I2: =C2 -> ESG | J2: Sum of euro positions | K2: Rebalancing | L2: =F2 -> Date | M2: =G2 -> L&MC | N2: =H2 -> Cons Hyb | P2: Date | Q2: =G2 -> L&MC | R2: =H2 -> Cons Hyb | S2: =I2 -> ESG | T2: Sum of weights
A3: {=TRANSPOSE('2FST Optimality'!E19:E21)} -> 0.28099024 | B3: 0.15 | C3: 0.56900876 | F3: =Constituents!A5 -> 44141 | G3: =A3*$C$5 -> 280.99024 | H3: =B3*$C$5 -> 150 | I3: =C3*$C$5 -> 569.00876 | J3: =SUM(G3:I3) -> 999.999 | K3: TRUE | L3: =G3 -> 280.99024 | M3: =H3 -> 150 | N3: =I3 -> 569.00876 | P3: =Constituents!G5 -> 44141 | Q3: =L3/$J3 -> 0.28099052 | R3: =M3/$J3 -> 0.15000015 | S3: =N3/$J3 -> 0.56900933 | T3: =SUM(Q3:S3) -> 1
F4: =Constituents!A6 -> 44144 | G4: =L3*(1+Constituents!H6) -> 284.03426 | H4: =M3*(1+Constituents!I6) -> 150.47906 | I4: =N3*(1+Constituents!J6) -> 570.60753 | J4: =SUM(G4:I4) -> 1005.1208 | K4: =MOD(DAY(F4)-1,$D$9)=0 -> FALSE | L4: =IF($K4=FALSE,G4,A$3*$J4) -> 284.03426 | M4: =IF($K4=FALSE,H4,B$3*$J4) -> 150.47906 | N4: =IF($K4=FALSE,I4,C$3*$J4) -> 570.60753 | P4: =Constituents!G6 -> 44144 | Q4: =L4/$J4 -> 0.28258717 | R4: =M4/$J4 -> 0.14971241 | S4: =N4/$J4 -> 0.56770042 | T4: =SUM(Q4:S4) -> 1 | AE4: =J4/J3 -1 -> 0.0051218514
A5: Initial portfolio value | C5: 1000 | F5: =Constituents!A7 -> 44145 | G5: =L4*(1+Constituents!H7) -> 283.81287 | H5: =M4*(1+Constituents!I7) -> 150.66351 | I5: =N4*(1+Constituents!J7) -> 570.47713 | J5: =SUM(G5:I5) -> 1004.9535 | K5: =MOD(DAY(F5)-1,$D$9)=0 -> FALSE | L5: =IF($K5=FALSE,G5,A$3*$J5) -> 283.81287 | M5: =IF($K5=FALSE,H5,B$3*$J5) -> 150.66351 | N5: =IF($K5=FALSE,I5,C$3*$J5) -> 570.47713 | P5: =Constituents!G7 -> 44145 | Q5: =L5/$J5 -> 0.28241393 | R5: =M5/$J5 -> 0.14992088 | S5: =N5/$J5 -> 0.56766519 | T5: =SUM(Q5:S5) -> 1 | AE5: =J5/J4 -1 -> -0.00016647468
F6: =Constituents!A8 -> 44146 | G6: =L5*(1+Constituents!H8) -> 286.30343 | H6: =M5*(1+Constituents!I8) -> 150.86062 | I6: =N5*(1+Constituents!J8) -> 573.2438 | J6: =SUM(G6:I6) -> 1010.4079 | K6: =MOD(DAY(F6)-1,$D$9)=0 -> FALSE | L6: =IF($K6=FALSE,G6,A$3*$J6) -> 286.30343 | M6: =IF($K6=FALSE,H6,B$3*$J6) -> 150.86062 | N6: =IF($K6=FALSE,I6,C$3*$J6) -> 573.2438 | P6: =Constituents!G8 -> 44146 | Q6: =L6/$J6 -> 0.28335432 | R6: =M6/$J6 -> 0.14930666 | S6: =N6/$J6 -> 0.56733902 | T6: =SUM(Q6:S6) -> 1 | AE6: =J6/J5 -1 -> 0.0054274473
A7: Rebalancing | F7: =Constituents!A9 -> 44147 | G7: =L6*(1+Constituents!H9) -> 286.58016 | H7: =M6*(1+Constituents!I9) -> 150.93989 | I7: =N6*(1+Constituents!J9) -> 576.20889 | J7: =SUM(G7:I7) -> 1013.7289 | K7: =MOD(DAY(F7)-1,$D$9)=0 -> FALSE | L7: =IF($K7=FALSE,G7,A$3*$J7) -> 286.58016 | M7: =IF($K7=FALSE,H7,B$3*$J7) -> 150.93989 | N7: =IF($K7=FALSE,I7,C$3*$J7) -> 576.20889 | P7: =Constituents!G9 -> 44147 | Q7: =L7/$J7 -> 0.282699 | R7: =M7/$J7 -> 0.14889571 | S7: =N7/$J7 -> 0.56840529 | T7: =SUM(Q7:S7) -> 1 | AE7: =J7/J6 -1 -> 0.0032868785
A8: Rebalancing frequency | D8: M | F8: =Constituents!A10 -> 44148 | G8: =L7*(1+Constituents!H10) -> 287.74242 | H8: =M7*(1+Constituents!I10) -> 150.98133 | I8: =N7*(1+Constituents!J10) -> 578.20452 | J8: =SUM(G8:I8) -> 1016.9283 | K8: =MOD(DAY(F8)-1,$D$9)=0 -> FALSE | L8: =IF($K8=FALSE,G8,A$3*$J8) -> 287.74242 | M8: =IF($K8=FALSE,H8,B$3*$J8) -> 150.98133 | N8: =IF($K8=FALSE,I8,C$3*$J8) -> 578.20452 | P8: =Constituents!G10 -> 44148 | Q8: =L8/$J8 -> 0.28295252 | R8: =M8/$J8 -> 0.14846803 | S8: =N8/$J8 -> 0.56857945 | T8: =SUM(Q8:S8) -> 1 | AE8: =J8/J7 -1 -> 0.0031559998
A9: Rebalancing frequency (in days) | D9: 30 | F9: =Constituents!A11 -> 44152 | G9: =L8*(1+Constituents!H11) -> 293.00026 | H9: =M8*(1+Constituents!I11) -> 151.67679 | I9: =N8*(1+Constituents!J11) -> 584.32746 | J9: =SUM(G9:I9) -> 1029.0045 | K9: =MOD(DAY(F9)-1,$D$9)=0 -> FALSE | L9: =IF($K9=FALSE,G9,A$3*$J9) -> 293.00026 | M9: =IF($K9=FALSE,H9,B$3*$J9) -> 151.67679 | N9: =IF($K9=FALSE,I9,C$3*$J9) -> 584.32746 | P9: =Constituents!G11 -> 44152 | Q9: =L9/$J9 -> 0.28474147 | R9: =M9/$J9 -> 0.14740148 | S9: =N9/$J9 -> 0.56785704 | T9: =SUM(Q9:S9) -> 1 | AE9: =J9/J8 -1 -> 0.011875224
F10: =Constituents!A12 -> 44153 | G10: =L9*(1+Constituents!H12) -> 294.54994 | H10: =M9*(1+Constituents!I12) -> 151.99054 | I10: =N9*(1+Constituents!J12) -> 587.30389 | J10: =SUM(G10:I10) -> 1033.8444 | K10: =MOD(DAY(F10)-1,$D$9)=0 -> FALSE | L10: =IF($K10=FALSE,G10,A$3*$J10) -> 294.54994 | M10: =IF($K10=FALSE,H10,B$3*$J10) -> 151.99054 | N10: =IF($K10=FALSE,I10,C$3*$J10) -> 587.30389 | P10: =Constituents!G12 -> 44153 | Q10: =L10/$J10 -> 0.28490743 | R10: =M10/$J10 -> 0.14701491 | S10: =N10/$J10 -> 0.56807766 | T10: =SUM(Q10:S10) -> 1 | AE10: =J10/J9 -1 -> 0.0047034402
F11: =Constituents!A13 -> 44154 | G11: =L10*(1+Constituents!H13) -> 291.78266 | H11: =M10*(1+Constituents!I13) -> 151.64168 | I11: =N10*(1+Constituents!J13) -> 583.0972 | J11: =SUM(G11:I11) -> 1026.5215 | K11: =MOD(DAY(F11)-1,$D$9)=0 -> FALSE | L11: =IF($K11=FALSE,G11,A$3*$J11) -> 291.78266 | M11: =IF($K11=FALSE,H11,B$3*$J11) -> 151.64168 | N11: =IF($K11=FALSE,I11,C$3*$J11) -> 583.0972 | P11: =Constituents!G13 -> 44154 | Q11: =L11/$J11 -> 0.28424407 | R11: =M11/$J11 -> 0.14772382 | S11: =N11/$J11 -> 0.56803212 | T11: =SUM(Q11:S11) -> 1 | AE11: =J11/J10 -1 -> -0.0070831142
A12: Returns | F12: =Constituents!A14 -> 44155 | G12: =L11*(1+Constituents!H14) -> 293.99649 | H12: =M11*(1+Constituents!I14) -> 152.54917 | I12: =N11*(1+Constituents!J14) -> 584.16305 | J12: =SUM(G12:I12) -> 1030.7087 | K12: =MOD(DAY(F12)-1,$D$9)=0 -> FALSE | L12: =IF($K12=FALSE,G12,A$3*$J12) -> 293.99649 | M12: =IF($K12=FALSE,H12,B$3*$J12) -> 152.54917 | N12: =IF($K12=FALSE,I12,C$3*$J12) -> 584.16305 | P12: =Constituents!G14 -> 44155 | Q12: =L12/$J12 -> 0.28523722 | R12: =M12/$J12 -> 0.14800416 | S12: =N12/$J12 -> 0.56675862 | T12: =SUM(Q12:S12) -> 1 | AE12: =J12/J11 -1 -> 0.0040789849
A13: Time Frame (Years) | C13: =COUNT(F3:F1209)/252 -> 4.7896825 | F13: =Constituents!A15 -> 44158 | G13: =L12*(1+Constituents!H15) -> 296.32101 | H13: =M12*(1+Constituents!I15) -> 152.92938 | I13: =N12*(1+Constituents!J15) -> 585.58607 | J13: =SUM(G13:I13) -> 1034.8365 | K13: =MOD(DAY(F13)-1,$D$9)=0 -> FALSE | L13: =IF($K13=FALSE,G13,A$3*$J13) -> 296.32101 | M13: =IF($K13=FALSE,H13,B$3*$J13) -> 152.92938 | N13: =IF($K13=FALSE,I13,C$3*$J13) -> 585.58607 | P13: =Constituents!G15 -> 44158 | Q13: =L13/$J13 -> 0.28634574 | R13: =M13/$J13 -> 0.1477812 | S13: =N13/$J13 -> 0.56587306 | T13: =SUM(Q13:S13) -> 1 | AE13: =J13/J12 -1 -> 0.0040047631
A14: GM | C14: =(J1209/J3)^(1/C13) -1 -> 0.2530678 | F14: =Constituents!A16 -> 44159 | G14: =L13*(1+Constituents!H16) -> 298.9776 | H14: =M13*(1+Constituents!I16) -> 153.55025 | I14: =N13*(1+Constituents!J16) -> 593.767 | J14: =SUM(G14:I14) -> 1046.2949 | K14: =MOD(DAY(F14)-1,$D$9)=0 -> FALSE | L14: =IF($K14=FALSE,G14,A$3*$J14) -> 298.9776 | M14: =IF($K14=FALSE,H14,B$3*$J14) -> 153.55025 | N14: =IF($K14=FALSE,I14,C$3*$J14) -> 593.767 | P14: =Constituents!G16 -> 44159 | Q14: =L14/$J14 -> 0.2857489 | R14: =M14/$J14 -> 0.14675619 | S14: =N14/$J14 -> 0.56749491 | T14: =SUM(Q14:S14) -> 1 | AE14: =J14/J13 -1 -> 0.011072666
A15: Excess Return over Benchmark | C15: =C14-C20 -> 0.056329808 | F15: =Constituents!A17 -> 44160 | G15: =L14*(1+Constituents!H17) -> 294.21787 | H15: =M14*(1+Constituents!I17) -> 153.44777 | I15: =N14*(1+Constituents!J17) -> 585.92056 | J15: =SUM(G15:I15) -> 1033.5862 | K15: =MOD(DAY(F15)-1,$D$9)=0 -> FALSE | L15: =IF($K15=FALSE,G15,A$3*$J15) -> 294.21787 | M15: =IF($K15=FALSE,H15,B$3*$J15) -> 153.44777 | N15: =IF($K15=FALSE,I15,C$3*$J15) -> 585.92056 | P15: =Constituents!G17 -> 44160 | Q15: =L15/$J15 -> 0.28465731 | R15: =M15/$J15 -> 0.14846151 | S15: =N15/$J15 -> 0.56688118 | T15: =SUM(Q15:S15) -> 1 | AE15: =J15/J14 -1 -> -0.012146334
F16: =Constituents!A18 -> 44161 | G16: =L15*(1+Constituents!H18) -> 296.15497 | H16: =M15*(1+Constituents!I18) -> 153.93045 | I16: =N15*(1+Constituents!J18) -> 596.21051 | J16: =SUM(G16:I16) -> 1046.2959 | K16: =MOD(DAY(F16)-1,$D$9)=0 -> FALSE | L16: =IF($K16=FALSE,G16,A$3*$J16) -> 296.15497 | M16: =IF($K16=FALSE,H16,B$3*$J16) -> 153.93045 | N16: =IF($K16=FALSE,I16,C$3*$J16) -> 596.21051 | P16: =Constituents!G18 -> 44161 | Q16: =L16/$J16 -> 0.28305087 | R16: =M16/$J16 -> 0.14711942 | S16: =N16/$J16 -> 0.56982971 | T16: =SUM(Q16:S16) -> 1 | AE16: =J16/J15 -1 -> 0.01229673
A17: Returns - NIFTY 500 | F17: =Constituents!A19 -> 44162 | G17: =L16*(1+Constituents!H19) -> 300.25055 | H17: =M16*(1+Constituents!I19) -> 154.14293 | I17: =N16*(1+Constituents!J19) -> 600.31515 | J17: =SUM(G17:I17) -> 1054.7086 | K17: =MOD(DAY(F17)-1,$D$9)=0 -> FALSE | L17: =IF($K17=FALSE,G17,A$3*$J17) -> 300.25055 | M17: =IF($K17=FALSE,H17,B$3*$J17) -> 154.14293 | N17: =IF($K17=FALSE,I17,C$3*$J17) -> 600.31515 | P17: =Constituents!G19 -> 44162 | Q17: =L17/$J17 -> 0.2846763 | R17: =M17/$J17 -> 0.14614741 | S17: =N17/$J17 -> 0.56917629 | T17: =SUM(Q17:S17) -> 1 | AE17: =J17/J16 -1 -> 0.0080404654
A18: Time Frame (Years) | C18: =COUNT(F3:F1209)/252 -> 4.7896825 | F18: =Constituents!A20 -> 44166 | G18: =L17*(1+Constituents!H20) -> 304.34614 | H18: =M17*(1+Constituents!I20) -> 154.70488 | I18: =N17*(1+Constituents!J20) -> 609.85108 | J18: =SUM(G18:I18) -> 1068.9021 | K18: =MOD(DAY(F18)-1,$D$9)=0 -> TRUE | L18: =IF($K18=FALSE,G18,A$3*$J18) -> 300.35106 | M18: =IF($K18=FALSE,H18,B$3*$J18) -> 160.33531 | N18: =IF($K18=FALSE,I18,C$3*$J18) -> 608.21465 | P18: =Constituents!G20 -> 44166 | Q18: =L18/$J18 -> 0.28099024 | R18: =M18/$J18 -> 0.15 | S18: =N18/$J18 -> 0.56900876 | T18: =SUM(Q18:S18) -> 0.999999 | AE18: =J18/J17 -1 -> 0.013457223
A19: Standard Deviation (Ann.) | C19: =_xlfn.STDEV.S(Constituents!K6:K1211) * SQRT(252) -> 0.14651787 | F19: =Constituents!A21 -> 44167 | G19: =L18*(1+Constituents!H21) -> 301.71654 | H19: =M18*(1+Constituents!I21) -> 160.38451 | I19: =N18*(1+Constituents!J21) -> 611.91814 | J19: =SUM(G19:I19) -> 1074.0192 | K19: =MOD(DAY(F19)-1,$D$9)=0 -> FALSE | L19: =IF($K19=FALSE,G19,A$3*$J19) -> 301.71654 | M19: =IF($K19=FALSE,H19,B$3*$J19) -> 160.38451 | N19: =IF($K19=FALSE,I19,C$3*$J19) -> 611.91814 | P19: =Constituents!G21 -> 44167 | Q19: =L19/$J19 -> 0.28092285 | R19: =M19/$J19 -> 0.14933114 | S19: =N19/$J19 -> 0.569746 | T19: =SUM(Q19:S19) -> 1 | AE19: =J19/J18 -1 -> 0.0047872459
A20: GM | C20: =(Constituents!E1211/Constituents!E5)^(1/C18) -1 -> 0.19673799 | F20: =Constituents!A22 -> 44168 | G20: =L19*(1+Constituents!H22) -> 301.49806 | H20: =M19*(1+Constituents!I22) -> 161.00798 | I20: =N19*(1+Constituents!J22) -> 614.75654 | J20: =SUM(G20:I20) -> 1077.2626 | K20: =MOD(DAY(F20)-1,$D$9)=0 -> FALSE | L20: =IF($K20=FALSE,G20,A$3*$J20) -> 301.49806 | M20: =IF($K20=FALSE,H20,B$3*$J20) -> 161.00798 | N20: =IF($K20=FALSE,I20,C$3*$J20) -> 614.75654 | P20: =Constituents!G22 -> 44168 | Q20: =L20/$J20 -> 0.27987425 | R20: =M20/$J20 -> 0.14946029 | S20: =N20/$J20 -> 0.57066545 | T20: =SUM(Q20:S20) -> 1 | AE20: =J20/J19 -1 -> 0.0030198665
F21: =Constituents!A23 -> 44169 | G21: =L20*(1+Constituents!H23) -> 303.57359 | H21: =M20*(1+Constituents!I23) -> 161.68924 | I21: =N20*(1+Constituents!J23) -> 621.85254 | J21: =SUM(G21:I21) -> 1087.1154 | K21: =MOD(DAY(F21)-1,$D$9)=0 -> FALSE | L21: =IF($K21=FALSE,G21,A$3*$J21) -> 303.57359 | M21: =IF($K21=FALSE,H21,B$3*$J21) -> 161.68924 | N21: =IF($K21=FALSE,I21,C$3*$J21) -> 621.85254 | P21: =Constituents!G23 -> 44169 | Q21: =L21/$J21 -> 0.27924689 | R21: =M21/$J21 -> 0.14873237 | S21: =N21/$J21 -> 0.57202074 | T21: =SUM(Q21:S21) -> 1 | AE21: =J21/J20 -1 -> 0.0091461332
A22: Sharpe Ratio | F22: =Constituents!A24 -> 44172 | G22: =L21*(1+Constituents!H24) -> 306.41379 | H22: =M21*(1+Constituents!I24) -> 162.1531 | I22: =N21*(1+Constituents!J24) -> 628.8298 | J22: =SUM(G22:I22) -> 1097.3967 | K22: =MOD(DAY(F22)-1,$D$9)=0 -> FALSE | L22: =IF($K22=FALSE,G22,A$3*$J22) -> 306.41379 | M22: =IF($K22=FALSE,H22,B$3*$J22) -> 162.1531 | N22: =IF($K22=FALSE,I22,C$3*$J22) -> 628.8298 | P22: =Constituents!G24 -> 44172 | Q22: =L22/$J22 -> 0.2792188 | R22: =M22/$J22 -> 0.14776161 | S22: =N22/$J22 -> 0.57301959 | T22: =SUM(Q22:S22) -> 1 | AE22: =J22/J21 -1 -> 0.0094574277
A23: Expected Returns | C23: =C14 -> 0.2530678 | F23: =Constituents!A25 -> 44173 | G23: =L22*(1+Constituents!H25) -> 305.81298 | H23: =M22*(1+Constituents!I25) -> 162.11312 | I23: =N22*(1+Constituents!J25) -> 624.48173 | J23: =SUM(G23:I23) -> 1092.4078 | K23: =MOD(DAY(F23)-1,$D$9)=0 -> FALSE | L23: =IF($K23=FALSE,G23,A$3*$J23) -> 305.81298 | M23: =IF($K23=FALSE,H23,B$3*$J23) -> 162.11312 | N23: =IF($K23=FALSE,I23,C$3*$J23) -> 624.48173 | P23: =Constituents!G25 -> 44173 | Q23: =L23/$J23 -> 0.27994396 | R23: =M23/$J23 -> 0.14839981 | S23: =N23/$J23 -> 0.57165622 | T23: =SUM(Q23:S23) -> 1 | AE23: =J23/J22 -1 -> -0.0045460855
A24: Risk-free Rate | C24: 0.0655 | F24: =Constituents!A26 -> 44174 | G24: =L23*(1+Constituents!H26) -> 308.1616 | H24: =M23*(1+Constituents!I26) -> 162.33958 | I24: =N23*(1+Constituents!J26) -> 630.65044 | J24: =SUM(G24:I24) -> 1101.1516 | K24: =MOD(DAY(F24)-1,$D$9)=0 -> FALSE | L24: =IF($K24=FALSE,G24,A$3*$J24) -> 308.1616 | M24: =IF($K24=FALSE,H24,B$3*$J24) -> 162.33958 | N24: =IF($K24=FALSE,I24,C$3*$J24) -> 630.65044 | P24: =Constituents!G26 -> 44174 | Q24: =L24/$J24 -> 0.27985392 | R24: =M24/$J24 -> 0.14742709 | S24: =N24/$J24 -> 0.57271899 | T24: =SUM(Q24:S24) -> 1 | AE24: =J24/J23 -1 -> 0.0080041535
A25: Standard Deviation (Ann.) | C25: =_xlfn.STDEV.S(AE4:AE1209) * SQRT(252) -> 0.14214288 | F25: =Constituents!A27 -> 44175 | G25: =L24*(1+Constituents!H27) -> 305.70374 | H25: =M24*(1+Constituents!I27) -> 162.01722 | I25: =N24*(1+Constituents!J27) -> 634.74407 | J25: =SUM(G25:I25) -> 1102.465 | K25: =MOD(DAY(F25)-1,$D$9)=0 -> FALSE | L25: =IF($K25=FALSE,G25,A$3*$J25) -> 305.70374 | M25: =IF($K25=FALSE,H25,B$3*$J25) -> 162.01722 | N25: =IF($K25=FALSE,I25,C$3*$J25) -> 634.74407 | P25: =Constituents!G27 -> 44175 | Q25: =L25/$J25 -> 0.2772911 | R25: =M25/$J25 -> 0.14695906 | S25: =N25/$J25 -> 0.57574985 | T25: =SUM(Q25:S25) -> 1 | AE25: =J25/J24 -1 -> 0.0011927571
A26: Share Ratio | C26: =(C23-C24)/C25 -> 1.3195723 | F26: =Constituents!A28 -> 44176 | G26: =L25*(1+Constituents!H28) -> 305.97683 | H26: =M25*(1+Constituents!I28) -> 162.35316 | I26: =N25*(1+Constituents!J28) -> 635.30384 | J26: =SUM(G26:I26) -> 1103.6338 | K26: =MOD(DAY(F26)-1,$D$9)=0 -> FALSE | L26: =IF($K26=FALSE,G26,A$3*$J26) -> 305.97683 | M26: =IF($K26=FALSE,H26,B$3*$J26) -> 162.35316 | N26: =IF($K26=FALSE,I26,C$3*$J26) -> 635.30384 | P26: =Constituents!G28 -> 44176 | Q26: =L26/$J26 -> 0.27724488 | R26: =M26/$J26 -> 0.14710782 | S26: =N26/$J26 -> 0.5756473 | T26: =SUM(Q26:S26) -> 1 | AE26: =J26/J25 -1 -> 0.0010601735
F27: =Constituents!A29 -> 44179 | G27: =L26*(1+Constituents!H29) -> 307.17846 | H27: =M26*(1+Constituents!I29) -> 162.47639 | I27: =N26*(1+Constituents!J29) -> 635.91449 | J27: =SUM(G27:I27) -> 1105.5693 | K27: =MOD(DAY(F27)-1,$D$9)=0 -> FALSE | L27: =IF($K27=FALSE,G27,A$3*$J27) -> 307.17846 | M27: =IF($K27=FALSE,H27,B$3*$J27) -> 162.47639 | N27: =IF($K27=FALSE,I27,C$3*$J27) -> 635.91449 | P27: =Constituents!G29 -> 44179 | Q27: =L27/$J27 -> 0.2778464 | R27: =M27/$J27 -> 0.14696174 | S27: =N27/$J27 -> 0.57519186 | T27: =SUM(Q27:S27) -> 1 | AE27: =J27/J26 -1 -> 0.0017537526
F28: =Constituents!A30 -> 44180 | G28: =L27*(1+Constituents!H30) -> 307.0146 | H28: =M27*(1+Constituents!I30) -> 162.10999 | I28: =N27*(1+Constituents!J30) -> 638.31751 | J28: =SUM(G28:I28) -> 1107.4421 | K28: =MOD(DAY(F28)-1,$D$9)=0 -> FALSE | L28: =IF($K28=FALSE,G28,A$3*$J28) -> 307.0146 | M28: =IF($K28=FALSE,H28,B$3*$J28) -> 162.10999 | N28: =IF($K28=FALSE,I28,C$3*$J28) -> 638.31751 | P28: =Constituents!G30 -> 44180 | Q28: =L28/$J28 -> 0.27722858 | R28: =M28/$J28 -> 0.14638236 | S28: =N28/$J28 -> 0.57638906 | T28: =SUM(Q28:S28) -> 1 | AE28: =J28/J27 -1 -> 0.0016939419
F29: =Constituents!A31 -> 44181 | G29: =L28*(1+Constituents!H31) -> 309.80018 | H29: =M28*(1+Constituents!I31) -> 162.33395 | I29: =N28*(1+Constituents!J31) -> 641.46689 | J29: =SUM(G29:I29) -> 1113.601 | K29: =MOD(DAY(F29)-1,$D$9)=0 -> FALSE | L29: =IF($K29=FALSE,G29,A$3*$J29) -> 309.80018 | M29: =IF($K29=FALSE,H29,B$3*$J29) -> 162.33395 | N29: =IF($K29=FALSE,I29,C$3*$J29) -> 641.46689 | P29: =Constituents!G31 -> 44181 | Q29: =L29/$J29 -> 0.27819674 | R29: =M29/$J29 -> 0.14577389 | S29: =N29/$J29 -> 0.57602937 | T29: =SUM(Q29:S29) -> 1 | AE29: =J29/J28 -1 -> 0.0055613939
F30: =Constituents!A32 -> 44182 | G30: =L29*(1+Constituents!H32) -> 309.30861 | H30: =M29*(1+Constituents!I32) -> 162.37769 | I30: =N29*(1+Constituents!J32) -> 642.78997 | J30: =SUM(G30:I30) -> 1114.4763 | K30: =MOD(DAY(F30)-1,$D$9)=0 -> FALSE | L30: =IF($K30=FALSE,G30,A$3*$J30) -> 309.30861 | M30: =IF($K30=FALSE,H30,B$3*$J30) -> 162.37769 | N30: =IF($K30=FALSE,I30,C$3*$J30) -> 642.78997 | P30: =Constituents!G32 -> 44182 | Q30: =L30/$J30 -> 0.27753719 | R30: =M30/$J30 -> 0.14569865 | S30: =N30/$J30 -> 0.57676417 | T30: =SUM(Q30:S30) -> 1 | AE30: =J30/J29 -1 -> 0.00078595121
F31: =Constituents!A33 -> 44183 | G31: =L30*(1+Constituents!H33) -> 309.90942 | H31: =M30*(1+Constituents!I33) -> 162.5145 | I31: =N30*(1+Constituents!J33) -> 650.55882 | J31: =SUM(G31:I31) -> 1122.9827 | K31: =MOD(DAY(F31)-1,$D$9)=0 -> FALSE | L31: =IF($K31=FALSE,G31,A$3*$J31) -> 309.90942 | M31: =IF($K31=FALSE,H31,B$3*$J31) -> 162.5145 | N31: =IF($K31=FALSE,I31,C$3*$J31) -> 650.55882 | P31: =Constituents!G33 -> 44183 | Q31: =L31/$J31 -> 0.27596989 | R31: =M31/$J31 -> 0.14471683 | S31: =N31/$J31 -> 0.57931329 | T31: =SUM(Q31:S31) -> 1 | AE31: =J31/J30 -1 -> 0.007632707
F32: =Constituents!A34 -> 44186 | G32: =L31*(1+Constituents!H34) -> 297.29238 | H32: =M31*(1+Constituents!I34) -> 160.67547 | I32: =N31*(1+Constituents!J34) -> 629.5083 | J32: =SUM(G32:I32) -> 1087.4762 | K32: =MOD(DAY(F32)-1,$D$9)=0 -> FALSE | L32: =IF($K32=FALSE,G32,A$3*$J32) -> 297.29238 | M32: =IF($K32=FALSE,H32,B$3*$J32) -> 160.67547 | N32: =IF($K32=FALSE,I32,C$3*$J32) -> 629.5083 | P32: =Constituents!G34 -> 44186 | Q32: =L32/$J32 -> 0.2733783 | R32: =M32/$J32 -> 0.1477508 | S32: =N32/$J32 -> 0.5788709 | T32: =SUM(Q32:S32) -> 1 | AE32: =J32/J31 -1 -> -0.0316181
F33: =Constituents!A35 -> 44187 | G33: =L32*(1+Constituents!H35) -> 300.84263 | H33: =M32*(1+Constituents!I35) -> 161.22133 | I33: =N32*(1+Constituents!J35) -> 642.10016 | J33: =SUM(G33:I33) -> 1104.1641 | K33: =MOD(DAY(F33)-1,$D$9)=0 -> FALSE | L33: =IF($K33=FALSE,G33,A$3*$J33) -> 300.84263 | M33: =IF($K33=FALSE,H33,B$3*$J33) -> 161.22133 | N33: =IF($K33=FALSE,I33,C$3*$J33) -> 642.10016 | P33: =Constituents!G35 -> 44187 | Q33: =L33/$J33 -> 0.27246188 | R33: =M33/$J33 -> 0.1460121 | S33: =N33/$J33 -> 0.58152602 | T33: =SUM(Q33:S33) -> 1 | AE33: =J33/J32 -1 -> 0.015345589
F34: =Constituents!A36 -> 44188 | G34: =L33*(1+Constituents!H36) -> 306.08607 | H34: =M33*(1+Constituents!I36) -> 162.03627 | I34: =N33*(1+Constituents!J36) -> 651.93278 | J34: =SUM(G34:I34) -> 1120.0551 | K34: =MOD(DAY(F34)-1,$D$9)=0 -> FALSE | L34: =IF($K34=FALSE,G34,A$3*$J34) -> 306.08607 | M34: =IF($K34=FALSE,H34,B$3*$J34) -> 162.03627 | N34: =IF($K34=FALSE,I34,C$3*$J34) -> 651.93278 | P34: =Constituents!G36 -> 44188 | Q34: =L34/$J34 -> 0.27327768 | R34: =M34/$J34 -> 0.14466812 | S34: =N34/$J34 -> 0.58205419 | T34: =SUM(Q34:S34) -> 1 | AE34: =J34/J33 -1 -> 0.014391897
F35: =Constituents!A37 -> 44189 | G35: =L34*(1+Constituents!H37) -> 307.88851 | H35: =M34*(1+Constituents!I37) -> 162.63242 | I35: =N34*(1+Constituents!J37) -> 655.18959 | J35: =SUM(G35:I35) -> 1125.7105 | K35: =MOD(DAY(F35)-1,$D$9)=0 -> FALSE | L35: =IF($K35=FALSE,G35,A$3*$J35) -> 307.88851 | M35: =IF($K35=FALSE,H35,B$3*$J35) -> 162.63242 | N35: =IF($K35=FALSE,I35,C$3*$J35) -> 655.18959 | P35: =Constituents!G37 -> 44189 | Q35: =L35/$J35 -> 0.27350594 | R35: =M35/$J35 -> 0.1444709 | S35: =N35/$J35 -> 0.58202316 | T35: =SUM(Q35:S35) -> 1 | AE35: =J35/J34 -1 -> 0.0050492009
F36: =Constituents!A38 -> 44193 | G36: =L35*(1+Constituents!H38) -> 310.45561 | H36: =M35*(1+Constituents!I38) -> 163.39005 | I36: =N35*(1+Constituents!J38) -> 658.61037 | J36: =SUM(G36:I36) -> 1132.456 | K36: =MOD(DAY(F36)-1,$D$9)=0 -> FALSE | L36: =IF($K36=FALSE,G36,A$3*$J36) -> 310.45561 | M36: =IF($K36=FALSE,H36,B$3*$J36) -> 163.39005 | N36: =IF($K36=FALSE,I36,C$3*$J36) -> 658.61037 | P36: =Constituents!G38 -> 44193 | Q36: =L36/$J36 -> 0.27414363 | R36: =M36/$J36 -> 0.14427937 | S36: =N36/$J36 -> 0.58157699 | T36: =SUM(Q36:S36) -> 1 | AE36: =J36/J35 -1 -> 0.0059922281
F37: =Constituents!A39 -> 44194 | G37: =L36*(1+Constituents!H39) -> 311.32952 | H37: =M36*(1+Constituents!I39) -> 163.38661 | I37: =N36*(1+Constituents!J39) -> 661.98592 | J37: =SUM(G37:I37) -> 1136.702 | K37: =MOD(DAY(F37)-1,$D$9)=0 -> FALSE | L37: =IF($K37=FALSE,G37,A$3*$J37) -> 311.32952 | M37: =IF($K37=FALSE,H37,B$3*$J37) -> 163.38661 | N37: =IF($K37=FALSE,I37,C$3*$J37) -> 661.98592 | P37: =Constituents!G39 -> 44194 | Q37: =L37/$J37 -> 0.27388841 | R37: =M37/$J37 -> 0.14373741 | S37: =N37/$J37 -> 0.58237418 | T37: =SUM(Q37:S37) -> 1 | AE37: =J37/J36 -1 -> 0.0037493887
F38: =Constituents!A40 -> 44195 | G38: =L37*(1+Constituents!H40) -> 312.25804 | H38: =M37*(1+Constituents!I40) -> 163.57981 | I38: =N37*(1+Constituents!J40) -> 661.494 | J38: =SUM(G38:I38) -> 1137.3319 | K38: =MOD(DAY(F38)-1,$D$9)=0 -> FALSE | L38: =IF($K38=FALSE,G38,A$3*$J38) -> 312.25804 | M38: =IF($K38=FALSE,H38,B$3*$J38) -> 163.57981 | N38: =IF($K38=FALSE,I38,C$3*$J38) -> 661.494 | P38: =Constituents!G40 -> 44195 | Q38: =L38/$J38 -> 0.27455315 | R38: =M38/$J38 -> 0.14382768 | S38: =N38/$J38 -> 0.58161917 | T38: =SUM(Q38:S38) -> 1 | AE38: =J38/J37 -1 -> 0.00055406608
... F1209: =Constituents!A1211 -> 45950 | G1209: =L1208*(1+Constituents!H1211) -> 832.31607 | H1209: =M1208*(1+Constituents!I1211) -> 436.50092 | I1209: =N1208*(1+Constituents!J1211) -> 1677.413 | J1209: =SUM(G1209:I1209) -> 2946.23 | K1209: =MOD(DAY(F1209)-1,$D$9)=0 -> FALSE | L1209: =IF($K1209=FALSE,G1209,A$3*$J1209) -> 832.31607 | M1209: =IF($K1209=FALSE,H1209,B$3*$J1209) -> 436.50092 | N1209: =IF($K1209=FALSE,I1209,C$3*$J1209) -> 1677.413 | P1209: =Constituents!G1211 -> 45950 | Q1209: =L1209/$J1209 -> 0.28250207 | R1209: =M1209/$J1209 -> 0.14815575 | S1209: =N1209/$J1209 -> 0.56934218 | T1209: =SUM(Q1209:S1209) -> 1 | AE1209: =J1209/J1208 -1 -> 0.0059519128

Sheet DashboardData
A1: Based on Solver Fixed Mix
B3: Cumulative Daily Returns | D3: Cumulative Excess Returns | G3: Rolling 12M Returns
A4: Category | B4: NIFTY 500 | C4: Portfolio | D4: Excess Returns | G4: NIFTY 500 | H4: Portfolio
A5: Fund | B5: Benchmark | C5: Large & Mid Cap, Conservative Hybrid, ESG | D5: Portfolio - NIFTY 500 | G5: Benchmark | H5: Large & Mid Cap, Conservative Hybrid, ESG
A6: 44141 | T6: Name | U6: Standard Deviation | V6: Returns
A7: 44144 | B7: =Constituents!E6/Constituents!E$5 -1 -> 0.014237305 | C7: ='Solver Fixed Mix'!J4/'Solver Fixed Mix'!J$3 -1 -> 0.0051218514 | D7: =C7-B7 -> -0.0091154536 | T7: NIFTY 500 | U7: ='Solver Fixed Mix'!C19 -> 0.14651787 | V7: ='Solver Fixed Mix'!C20 -> 0.19673799
A8: 44145 | B8: =Constituents!E7/Constituents!E$5 -1 -> 0.023471371 | C8: ='Solver Fixed Mix'!J5/'Solver Fixed Mix'!J$3 -1 -> 0.0049545241 | D8: =C8-B8 -> -0.018516847 | T8: Portfolio | U8: ='Solver Fixed Mix'!C25 -> 0.14214288 | V8: ='Solver Fixed Mix'!C14 -> 0.2530678
A9: 44146 | B9: =Constituents!E8/Constituents!E$5 -1 -> 0.032192156 | C9: ='Solver Fixed Mix'!J6/'Solver Fixed Mix'!J$3 -1 -> 0.010408862 | D9: =C9-B9 -> -0.021783294
A10: 44147 | B10: =Constituents!E9/Constituents!E$5 -1 -> 0.030816764 | C10: ='Solver Fixed Mix'!J7/'Solver Fixed Mix'!J$3 -1 -> 0.013729953 | D10: =C10-B10 -> -0.017086811
A11: 44148 | B11: =Constituents!E10/Constituents!E$5 -1 -> 0.035251906 | C11: ='Solver Fixed Mix'!J8/'Solver Fixed Mix'!J$3 -1 -> 0.016929285 | D11: =C11-B11 -> -0.018322622
A12: 44152 | B12: =Constituents!E11/Constituents!E$5 -1 -> 0.048886231 | C12: ='Solver Fixed Mix'!J9/'Solver Fixed Mix'!J$3 -1 -> 0.029005548 | D12: =C12-B12 -> -0.019880683
A13: 44153 | B13: =Constituents!E12/Constituents!E$5 -1 -> 0.055299746 | C13: ='Solver Fixed Mix'!J10/'Solver Fixed Mix'!J$3 -1 -> 0.033845414 | D13: =C13-B13 -> -0.021454332
A14: 44154 | B14: =Constituents!E13/Constituents!E$5 -1 -> 0.044251757 | C14: ='Solver Fixed Mix'!J11/'Solver Fixed Mix'!J$3 -1 -> 0.026522569 | D14: =C14-B14 -> -0.017729188
A15: 44155 | B15: =Constituents!E14/Constituents!E$5 -1 -> 0.052529028 | C15: ='Solver Fixed Mix'!J12/'Solver Fixed Mix'!J$3 -1 -> 0.030709739 | D15: =C15-B15 -> -0.021819289
A16: 44158 | B16: =Constituents!E15/Constituents!E$5 -1 -> 0.060043853 | C16: ='Solver Fixed Mix'!J13/'Solver Fixed Mix'!J$3 -1 -> 0.034837487 | D16: =C16-B16 -> -0.025206366
A17: 44159 | B17: =Constituents!E16/Constituents!E$5 -1 -> 0.06977625 | C17: ='Solver Fixed Mix'!J14/'Solver Fixed Mix'!J$3 -1 -> 0.046295897 | D17: =C17-B17 -> -0.023480353
A18: 44160 | B18: =Constituents!E17/Constituents!E$5 -1 -> 0.05396422 | C18: ='Solver Fixed Mix'!J15/'Solver Fixed Mix'!J$3 -1 -> 0.033587237 | D18: =C18-B18 -> -0.020376983
A19: 44161 | B19: =Constituents!E18/Constituents!E$5 -1 -> 0.063841132 | C19: ='Solver Fixed Mix'!J16/'Solver Fixed Mix'!J$3 -1 -> 0.046296979 | D19: =C19-B19 -> -0.017544153
A20: 44162 | B20: =Constituents!E19/Constituents!E$5 -1 -> 0.068326108 | C20: ='Solver Fixed Mix'!J17/'Solver Fixed Mix'!J$3 -1 -> 0.054709694 | D20: =C20-B20 -> -0.013616413
... A25: 44172 | B25: =Constituents!E24/Constituents!E$5 -1 -> 0.10332885 | C25: ='Solver Fixed Mix'!J22/'Solver Fixed Mix'!J$3 -1 -> 0.09739778 | D25: =C25-B25 -> -0.0059310679
A26: 44173 | B26: =Constituents!E25/Constituents!E$5 -1 -> 0.1051627 | C26: ='Solver Fixed Mix'!J23/'Solver Fixed Mix'!J$3 -1 -> 0.092408916 | D26: =C26-B26 -> -0.012753789 | T26: =OFFSET('Solver Fixed Mix'!A1,0,0) -> Target weights
A27: 44174 | B27: =Constituents!E26/Constituents!E$5 -1 -> 0.1143868 | C27: ='Solver Fixed Mix'!J24/'Solver Fixed Mix'!J$3 -1 -> 0.10115272 | D27: =C27-B27 -> -0.013234079 | T27: L&MC | U27: Cons Hyb | V27: ESG
A28: 44175 | B28: =Constituents!E27/Constituents!E$5 -1 -> 0.11041511 | C28: ='Solver Fixed Mix'!J25/'Solver Fixed Mix'!J$3 -1 -> 0.10246613 | D28: =C28-B28 -> -0.0079489768 | T28: ='Solver Fixed Mix'!A3 -> 0.28099024 | U28: ='Solver Fixed Mix'!B3 -> 0.15 | V28: ='Solver Fixed Mix'!C3 -> 0.56900876
A29: 44176 | B29: =Constituents!E28/Constituents!E$5 -1 -> 0.11341008 | C29: ='Solver Fixed Mix'!J26/'Solver Fixed Mix'!J$3 -1 -> 0.10363494 | D29: =C29-B29 -> -0.0097751383
A30: 44179 | B30: =Constituents!E29/Constituents!E$5 -1 -> 0.11778044 | C30: ='Solver Fixed Mix'!J27/'Solver Fixed Mix'!J$3 -1 -> 0.10557044 | D30: =C30-B30 -> -0.012209995
A31: 44180 | B31: =Constituents!E30/Constituents!E$5 -1 -> 0.11864255 | C31: ='Solver Fixed Mix'!J28/'Solver Fixed Mix'!J$3 -1 -> 0.10744321 | D31: =C31-B31 -> -0.011199335
A32: 44181 | B32: =Constituents!E31/Constituents!E$5 -1 -> 0.12823043 | C32: ='Solver Fixed Mix'!J29/'Solver Fixed Mix'!J$3 -1 -> 0.11360214 | D32: =C32-B32 -> -0.014628288
A33: 44182 | B33: =Constituents!E32/Constituents!E$5 -1 -> 0.13084666 | C33: ='Solver Fixed Mix'!J30/'Solver Fixed Mix'!J$3 -1 -> 0.11447738 | D33: =C33-B33 -> -0.016369286
A34: 44183 | B34: =Constituents!E33/Constituents!E$5 -1 -> 0.13170878 | C34: ='Solver Fixed Mix'!J31/'Solver Fixed Mix'!J$3 -1 -> 0.12298386 | D34: =C34-B34 -> -0.0087249188
A35: 44186 | B35: =Constituents!E34/Constituents!E$5 -1 -> 0.09276424 | C35: ='Solver Fixed Mix'!J32/'Solver Fixed Mix'!J$3 -1 -> 0.08747724 | D35: =C35-B35 -> -0.0052869994
A36: 44187 | B36: =Constituents!E35/Constituents!E$5 -1 -> 0.10387701 | C36: ='Solver Fixed Mix'!J33/'Solver Fixed Mix'!J$3 -1 -> 0.10416522 | D36: =C36-B36 -> 0.00028820688
A37: 44188 | B37: =Constituents!E36/Constituents!E$5 -1 -> 0.118807 | C37: ='Solver Fixed Mix'!J34/'Solver Fixed Mix'!J$3 -1 -> 0.12005625 | D37: =C37-B37 -> 0.0012492539
A38: 44189 | B38: =Constituents!E37/Constituents!E$5 -1 -> 0.12874371 | C38: ='Solver Fixed Mix'!J35/'Solver Fixed Mix'!J$3 -1 -> 0.12571164 | D38: =C38-B38 -> -0.0030320691
A39: 44193 | B39: =Constituents!E38/Constituents!E$5 -1 -> 0.13965217 | C39: ='Solver Fixed Mix'!J36/'Solver Fixed Mix'!J$3 -1 -> 0.13245716 | D39: =C39-B39 -> -0.0071950048
A40: 44194 | B40: =Constituents!E39/Constituents!E$5 -1 -> 0.14287138 | C40: ='Solver Fixed Mix'!J37/'Solver Fixed Mix'!J$3 -1 -> 0.13670318 | D40: =C40-B40 -> -0.0061681984
... A250: 44503 | B250: =Constituents!E249/Constituents!E$5 -1 -> 0.52317237 | C250: ='Solver Fixed Mix'!J247/'Solver Fixed Mix'!J$3 -1 -> 0.64435246 | D250: =C250-B250 -> 0.12118009
A251: 44508 | B251: =Constituents!E250/Constituents!E$5 -1 -> 0.54683311 | C251: ='Solver Fixed Mix'!J248/'Solver Fixed Mix'!J$3 -1 -> 0.67188257 | D251: =C251-B251 -> 0.12504946 | F251: Column1 | G251: NIFTY 500 | H251: Portfolio
A252: 44509 | B252: =Constituents!E251/Constituents!E$5 -1 -> 0.54900583 | C252: ='Solver Fixed Mix'!J249/'Solver Fixed Mix'!J$3 -1 -> 0.68695793 | D252: =C252-B252 -> 0.1379521 | F252: =A252 -> 44509 | G252: =(Constituents!E251/Constituents!E6)-1 -> 0.52726174 | H252: =('Solver Fixed Mix'!J249/'Solver Fixed Mix'!J4) -1 -> 0.67836161
A253: 44510 | B253: =Constituents!E252/Constituents!E$5 -1 -> 0.54692779 | C253: ='Solver Fixed Mix'!J250/'Solver Fixed Mix'!J$3 -1 -> 0.68574031 | D253: =C253-B253 -> 0.13881252 | F253: =A253 -> 44510 | G253: =(Constituents!E252/Constituents!E7)-1 -> 0.51145194 | H253: =('Solver Fixed Mix'!J250/'Solver Fixed Mix'!J5) -1 -> 0.67742945
A254: 44511 | B254: =Constituents!E253/Constituents!E$5 -1 -> 0.53596452 | C254: ='Solver Fixed Mix'!J251/'Solver Fixed Mix'!J$3 -1 -> 0.67126165 | D254: =C254-B254 -> 0.13529713 | F254: =A254 -> 44511 | G254: =(Constituents!E253/Constituents!E8)-1 -> 0.48806064 | H254: =('Solver Fixed Mix'!J251/'Solver Fixed Mix'!J6) -1 -> 0.65404493
...
